package net.minecraft.world.gen.structure;

import com.google.common.collect.Lists;
import java.util.List;
import java.util.Random;
import net.minecraft.block.BlockFlowerPot;
import net.minecraft.block.BlockLever;
import net.minecraft.block.BlockPlanks;
import net.minecraft.block.BlockSandStone;
import net.minecraft.block.BlockStoneBrick;
import net.minecraft.block.BlockStoneSlab;
import net.minecraft.block.BlockTripWire;
import net.minecraft.block.BlockTripWireHook;
import net.minecraft.entity.IEntityLivingData;
import net.minecraft.entity.monster.EntityWitch;
import net.minecraft.init.Blocks;
import net.minecraft.init.Items;
import net.minecraft.item.EnumDyeColor;
import net.minecraft.nbt.NBTTagCompound;
import net.minecraft.util.BlockPos;
import net.minecraft.util.EnumFacing;
import net.minecraft.util.WeightedRandomChestContent;
import net.minecraft.world.World;

public class ComponentScatteredFeaturePieces
{
    public static void registerScatteredFeaturePieces()
    {
        MapGenStructureIO.registerStructureComponent(ComponentScatteredFeaturePieces.DesertPyramid.class, "TeDP");
        MapGenStructureIO.registerStructureComponent(ComponentScatteredFeaturePieces.JunglePyramid.class, "TeJP");
        MapGenStructureIO.registerStructureComponent(ComponentScatteredFeaturePieces.SwampHut.class, "TeSH");
    }

    public static class DesertPyramid extends ComponentScatteredFeaturePieces.Feature
    {
        private boolean[] field_74940_h = new boolean[4];
        private static final List<WeightedRandomChestContent> itemsToGenerateInTemple = Lists.newArrayList(new WeightedRandomChestContent[] {new WeightedRandomChestContent(Items.field_151045_i, 0, 1, 3, 3), new WeightedRandomChestContent(Items.iron_ingot, 0, 1, 5, 10), new WeightedRandomChestContent(Items.gold_ingot, 0, 2, 7, 15), new WeightedRandomChestContent(Items.emerald, 0, 1, 3, 2), new WeightedRandomChestContent(Items.field_151103_aS, 0, 4, 6, 20), new WeightedRandomChestContent(Items.field_151078_bh, 0, 3, 7, 16), new WeightedRandomChestContent(Items.saddle, 0, 1, 1, 3), new WeightedRandomChestContent(Items.iron_horse_armor, 0, 1, 1, 1), new WeightedRandomChestContent(Items.golden_horse_armor, 0, 1, 1, 1), new WeightedRandomChestContent(Items.diamond_horse_armor, 0, 1, 1, 1)});

        public DesertPyramid()
        {
        }

        public DesertPyramid(Random p_i2062_1_, int p_i2062_2_, int p_i2062_3_)
        {
            super(p_i2062_1_, p_i2062_2_, 64, p_i2062_3_, 21, 15, 21);
        }

        protected void writeStructureToNBT(NBTTagCompound tagCompound)
        {
            super.writeStructureToNBT(tagCompound);
            tagCompound.setBoolean("hasPlacedChest0", this.field_74940_h[0]);
            tagCompound.setBoolean("hasPlacedChest1", this.field_74940_h[1]);
            tagCompound.setBoolean("hasPlacedChest2", this.field_74940_h[2]);
            tagCompound.setBoolean("hasPlacedChest3", this.field_74940_h[3]);
        }

        protected void readStructureFromNBT(NBTTagCompound tagCompound)
        {
            super.readStructureFromNBT(tagCompound);
            this.field_74940_h[0] = tagCompound.getBoolean("hasPlacedChest0");
            this.field_74940_h[1] = tagCompound.getBoolean("hasPlacedChest1");
            this.field_74940_h[2] = tagCompound.getBoolean("hasPlacedChest2");
            this.field_74940_h[3] = tagCompound.getBoolean("hasPlacedChest3");
        }

        public boolean addComponentParts(World worldIn, Random randomIn, StructureBoundingBox structureBoundingBoxIn)
        {
            this.fillWithBlocks(worldIn, structureBoundingBoxIn, 0, -4, 0, this.scatteredFeatureSizeX - 1, 0, this.scatteredFeatureSizeZ - 1, Blocks.sandstone.func_176223_P(), Blocks.sandstone.func_176223_P(), false);

            for (int i = 1; i <= 9; ++i)
            {
                this.fillWithBlocks(worldIn, structureBoundingBoxIn, i, i, i, this.scatteredFeatureSizeX - 1 - i, i, this.scatteredFeatureSizeZ - 1 - i, Blocks.sandstone.func_176223_P(), Blocks.sandstone.func_176223_P(), false);
                this.fillWithBlocks(worldIn, structureBoundingBoxIn, i + 1, i, i + 1, this.scatteredFeatureSizeX - 2 - i, i, this.scatteredFeatureSizeZ - 2 - i, Blocks.field_150350_a.func_176223_P(), Blocks.field_150350_a.func_176223_P(), false);
            }

            for (int j2 = 0; j2 < this.scatteredFeatureSizeX; ++j2)
            {
                for (int j = 0; j < this.scatteredFeatureSizeZ; ++j)
                {
                    int k = -5;
                    this.replaceAirAndLiquidDownwards(worldIn, Blocks.sandstone.func_176223_P(), j2, k, j, structureBoundingBoxIn);
                }
            }

            int k2 = this.getMetadataWithOffset(Blocks.sandstone_stairs, 3);
            int l2 = this.getMetadataWithOffset(Blocks.sandstone_stairs, 2);
            int i3 = this.getMetadataWithOffset(Blocks.sandstone_stairs, 0);
            int l = this.getMetadataWithOffset(Blocks.sandstone_stairs, 1);
            int i1 = ~EnumDyeColor.ORANGE.getDyeDamage() & 15;
            int j1 = ~EnumDyeColor.BLUE.getDyeDamage() & 15;
            this.fillWithBlocks(worldIn, structureBoundingBoxIn, 0, 0, 0, 4, 9, 4, Blocks.sandstone.func_176223_P(), Blocks.field_150350_a.func_176223_P(), false);
            this.fillWithBlocks(worldIn, structureBoundingBoxIn, 1, 10, 1, 3, 10, 3, Blocks.sandstone.func_176223_P(), Blocks.sandstone.func_176223_P(), false);
            this.setBlockState(worldIn, Blocks.sandstone_stairs.func_176203_a(k2), 2, 10, 0, structureBoundingBoxIn);
            this.setBlockState(worldIn, Blocks.sandstone_stairs.func_176203_a(l2), 2, 10, 4, structureBoundingBoxIn);
            this.setBlockState(worldIn, Blocks.sandstone_stairs.func_176203_a(i3), 0, 10, 2, structureBoundingBoxIn);
            this.setBlockState(worldIn, Blocks.sandstone_stairs.func_176203_a(l), 4, 10, 2, structureBoundingBoxIn);
            this.fillWithBlocks(worldIn, structureBoundingBoxIn, this.scatteredFeatureSizeX - 5, 0, 0, this.scatteredFeatureSizeX - 1, 9, 4, Blocks.sandstone.func_176223_P(), Blocks.field_150350_a.func_176223_P(), false);
            this.fillWithBlocks(worldIn, structureBoundingBoxIn, this.scatteredFeatureSizeX - 4, 10, 1, this.scatteredFeatureSizeX - 2, 10, 3, Blocks.sandstone.func_176223_P(), Blocks.sandstone.func_176223_P(), false);
            this.setBlockState(worldIn, Blocks.sandstone_stairs.func_176203_a(k2), this.scatteredFeatureSizeX - 3, 10, 0, structureBoundingBoxIn);
            this.setBlockState(worldIn, Blocks.sandstone_stairs.func_176203_a(l2), this.scatteredFeatureSizeX - 3, 10, 4, structureBoundingBoxIn);
            this.setBlockState(worldIn, Blocks.sandstone_stairs.func_176203_a(i3), this.scatteredFeatureSizeX - 5, 10, 2, structureBoundingBoxIn);
            this.setBlockState(worldIn, Blocks.sandstone_stairs.func_176203_a(l), this.scatteredFeatureSizeX - 1, 10, 2, structureBoundingBoxIn);
            this.fillWithBlocks(worldIn, structureBoundingBoxIn, 8, 0, 0, 12, 4, 4, Blocks.sandstone.func_176223_P(), Blocks.field_150350_a.func_176223_P(), false);
            this.fillWithBlocks(worldIn, structureBoundingBoxIn, 9, 1, 0, 11, 3, 4, Blocks.field_150350_a.func_176223_P(), Blocks.field_150350_a.func_176223_P(), false);
            this.setBlockState(worldIn, Blocks.sandstone.func_176203_a(BlockSandStone.EnumType.SMOOTH.getMetadata()), 9, 1, 1, structureBoundingBoxIn);
            this.setBlockState(worldIn, Blocks.sandstone.func_176203_a(BlockSandStone.EnumType.SMOOTH.getMetadata()), 9, 2, 1, structureBoundingBoxIn);
            this.setBlockState(worldIn, Blocks.sandstone.func_176203_a(BlockSandStone.EnumType.SMOOTH.getMetadata()), 9, 3, 1, structureBoundingBoxIn);
            this.setBlockState(worldIn, Blocks.sandstone.func_176203_a(BlockSandStone.EnumType.SMOOTH.getMetadata()), 10, 3, 1, structureBoundingBoxIn);
            this.setBlockState(worldIn, Blocks.sandstone.func_176203_a(BlockSandStone.EnumType.SMOOTH.getMetadata()), 11, 3, 1, structureBoundingBoxIn);
            this.setBlockState(worldIn, Blocks.sandstone.func_176203_a(BlockSandStone.EnumType.SMOOTH.getMetadata()), 11, 2, 1, structureBoundingBoxIn);
            this.setBlockState(worldIn, Blocks.sandstone.func_176203_a(BlockSandStone.EnumType.SMOOTH.getMetadata()), 11, 1, 1, structureBoundingBoxIn);
            this.fillWithBlocks(worldIn, structureBoundingBoxIn, 4, 1, 1, 8, 3, 3, Blocks.sandstone.func_176223_P(), Blocks.field_150350_a.func_176223_P(), false);
            this.fillWithBlocks(worldIn, structureBoundingBoxIn, 4, 1, 2, 8, 2, 2, Blocks.field_150350_a.func_176223_P(), Blocks.field_150350_a.func_176223_P(), false);
            this.fillWithBlocks(worldIn, structureBoundingBoxIn, 12, 1, 1, 16, 3, 3, Blocks.sandstone.func_176223_P(), Blocks.field_150350_a.func_176223_P(), false);
            this.fillWithBlocks(worldIn, structureBoundingBoxIn, 12, 1, 2, 16, 2, 2, Blocks.field_150350_a.func_176223_P(), Blocks.field_150350_a.func_176223_P(), false);
            this.fillWithBlocks(worldIn, structureBoundingBoxIn, 5, 4, 5, this.scatteredFeatureSizeX - 6, 4, this.scatteredFeatureSizeZ - 6, Blocks.sandstone.func_176223_P(), Blocks.sandstone.func_176223_P(), false);
            this.fillWithBlocks(worldIn, structureBoundingBoxIn, 9, 4, 9, 11, 4, 11, Blocks.field_150350_a.func_176223_P(), Blocks.field_150350_a.func_176223_P(), false);
            this.fillWithBlocks(worldIn, structureBoundingBoxIn, 8, 1, 8, 8, 3, 8, Blocks.sandstone.func_176203_a(BlockSandStone.EnumType.SMOOTH.getMetadata()), Blocks.sandstone.func_176203_a(BlockSandStone.EnumType.SMOOTH.getMetadata()), false);
            this.fillWithBlocks(worldIn, structureBoundingBoxIn, 12, 1, 8, 12, 3, 8, Blocks.sandstone.func_176203_a(BlockSandStone.EnumType.SMOOTH.getMetadata()), Blocks.sandstone.func_176203_a(BlockSandStone.EnumType.SMOOTH.getMetadata()), false);
            this.fillWithBlocks(worldIn, structureBoundingBoxIn, 8, 1, 12, 8, 3, 12, Blocks.sandstone.func_176203_a(BlockSandStone.EnumType.SMOOTH.getMetadata()), Blocks.sandstone.func_176203_a(BlockSandStone.EnumType.SMOOTH.getMetadata()), false);
            this.fillWithBlocks(worldIn, structureBoundingBoxIn, 12, 1, 12, 12, 3, 12, Blocks.sandstone.func_176203_a(BlockSandStone.EnumType.SMOOTH.getMetadata()), Blocks.sandstone.func_176203_a(BlockSandStone.EnumType.SMOOTH.getMetadata()), false);
            this.fillWithBlocks(worldIn, structureBoundingBoxIn, 1, 1, 5, 4, 4, 11, Blocks.sandstone.func_176223_P(), Blocks.sandstone.func_176223_P(), false);
            this.fillWithBlocks(worldIn, structureBoundingBoxIn, this.scatteredFeatureSizeX - 5, 1, 5, this.scatteredFeatureSizeX - 2, 4, 11, Blocks.sandstone.func_176223_P(), Blocks.sandstone.func_176223_P(), false);
            this.fillWithBlocks(worldIn, structureBoundingBoxIn, 6, 7, 9, 6, 7, 11, Blocks.sandstone.func_176223_P(), Blocks.sandstone.func_176223_P(), false);
            this.fillWithBlocks(worldIn, structureBoundingBoxIn, this.scatteredFeatureSizeX - 7, 7, 9, this.scatteredFeatureSizeX - 7, 7, 11, Blocks.sandstone.func_176223_P(), Blocks.sandstone.func_176223_P(), false);
            this.fillWithBlocks(worldIn, structureBoundingBoxIn, 5, 5, 9, 5, 7, 11, Blocks.sandstone.func_176203_a(BlockSandStone.EnumType.SMOOTH.getMetadata()), Blocks.sandstone.func_176203_a(BlockSandStone.EnumType.SMOOTH.getMetadata()), false);
            this.fillWithBlocks(worldIn, structureBoundingBoxIn, this.scatteredFeatureSizeX - 6, 5, 9, this.scatteredFeatureSizeX - 6, 7, 11, Blocks.sandstone.func_176203_a(BlockSandStone.EnumType.SMOOTH.getMetadata()), Blocks.sandstone.func_176203_a(BlockSandStone.EnumType.SMOOTH.getMetadata()), false);
            this.setBlockState(worldIn, Blocks.field_150350_a.func_176223_P(), 5, 5, 10, structureBoundingBoxIn);
            this.setBlockState(worldIn, Blocks.field_150350_a.func_176223_P(), 5, 6, 10, structureBoundingBoxIn);
            this.setBlockState(worldIn, Blocks.field_150350_a.func_176223_P(), 6, 6, 10, structureBoundingBoxIn);
            this.setBlockState(worldIn, Blocks.field_150350_a.func_176223_P(), this.scatteredFeatureSizeX - 6, 5, 10, structureBoundingBoxIn);
            this.setBlockState(worldIn, Blocks.field_150350_a.func_176223_P(), this.scatteredFeatureSizeX - 6, 6, 10, structureBoundingBoxIn);
            this.setBlockState(worldIn, Blocks.field_150350_a.func_176223_P(), this.scatteredFeatureSizeX - 7, 6, 10, structureBoundingBoxIn);
            this.fillWithBlocks(worldIn, structureBoundingBoxIn, 2, 4, 4, 2, 6, 4, Blocks.field_150350_a.func_176223_P(), Blocks.field_150350_a.func_176223_P(), false);
            this.fillWithBlocks(worldIn, structureBoundingBoxIn, this.scatteredFeatureSizeX - 3, 4, 4, this.scatteredFeatureSizeX - 3, 6, 4, Blocks.field_150350_a.func_176223_P(), Blocks.field_150350_a.func_176223_P(), false);
            this.setBlockState(worldIn, Blocks.sandstone_stairs.func_176203_a(k2), 2, 4, 5, structureBoundingBoxIn);
            this.setBlockState(worldIn, Blocks.sandstone_stairs.func_176203_a(k2), 2, 3, 4, structureBoundingBoxIn);
            this.setBlockState(worldIn, Blocks.sandstone_stairs.func_176203_a(k2), this.scatteredFeatureSizeX - 3, 4, 5, structureBoundingBoxIn);
            this.setBlockState(worldIn, Blocks.sandstone_stairs.func_176203_a(k2), this.scatteredFeatureSizeX - 3, 3, 4, structureBoundingBoxIn);
            this.fillWithBlocks(worldIn, structureBoundingBoxIn, 1, 1, 3, 2, 2, 3, Blocks.sandstone.func_176223_P(), Blocks.sandstone.func_176223_P(), false);
            this.fillWithBlocks(worldIn, structureBoundingBoxIn, this.scatteredFeatureSizeX - 3, 1, 3, this.scatteredFeatureSizeX - 2, 2, 3, Blocks.sandstone.func_176223_P(), Blocks.sandstone.func_176223_P(), false);
            this.setBlockState(worldIn, Blocks.sandstone_stairs.func_176223_P(), 1, 1, 2, structureBoundingBoxIn);
            this.setBlockState(worldIn, Blocks.sandstone_stairs.func_176223_P(), this.scatteredFeatureSizeX - 2, 1, 2, structureBoundingBoxIn);
            this.setBlockState(worldIn, Blocks.stone_slab.func_176203_a(BlockStoneSlab.EnumType.SAND.getMetadata()), 1, 2, 2, structureBoundingBoxIn);
            this.setBlockState(worldIn, Blocks.stone_slab.func_176203_a(BlockStoneSlab.EnumType.SAND.getMetadata()), this.scatteredFeatureSizeX - 2, 2, 2, structureBoundingBoxIn);
            this.setBlockState(worldIn, Blocks.sandstone_stairs.func_176203_a(l), 2, 1, 2, structureBoundingBoxIn);
            this.setBlockState(worldIn, Blocks.sandstone_stairs.func_176203_a(i3), this.scatteredFeatureSizeX - 3, 1, 2, structureBoundingBoxIn);
            this.fillWithBlocks(worldIn, structureBoundingBoxIn, 4, 3, 5, 4, 3, 18, Blocks.sandstone.func_176223_P(), Blocks.sandstone.func_176223_P(), false);
            this.fillWithBlocks(worldIn, structureBoundingBoxIn, this.scatteredFeatureSizeX - 5, 3, 5, this.scatteredFeatureSizeX - 5, 3, 17, Blocks.sandstone.func_176223_P(), Blocks.sandstone.func_176223_P(), false);
            this.fillWithBlocks(worldIn, structureBoundingBoxIn, 3, 1, 5, 4, 2, 16, Blocks.field_150350_a.func_176223_P(), Blocks.field_150350_a.func_176223_P(), false);
            this.fillWithBlocks(worldIn, structureBoundingBoxIn, this.scatteredFeatureSizeX - 6, 1, 5, this.scatteredFeatureSizeX - 5, 2, 16, Blocks.field_150350_a.func_176223_P(), Blocks.field_150350_a.func_176223_P(), false);

            for (int k1 = 5; k1 <= 17; k1 += 2)
            {
                this.setBlockState(worldIn, Blocks.sandstone.func_176203_a(BlockSandStone.EnumType.SMOOTH.getMetadata()), 4, 1, k1, structureBoundingBoxIn);
                this.setBlockState(worldIn, Blocks.sandstone.func_176203_a(BlockSandStone.EnumType.CHISELED.getMetadata()), 4, 2, k1, structureBoundingBoxIn);
                this.setBlockState(worldIn, Blocks.sandstone.func_176203_a(BlockSandStone.EnumType.SMOOTH.getMetadata()), this.scatteredFeatureSizeX - 5, 1, k1, structureBoundingBoxIn);
                this.setBlockState(worldIn, Blocks.sandstone.func_176203_a(BlockSandStone.EnumType.CHISELED.getMetadata()), this.scatteredFeatureSizeX - 5, 2, k1, structureBoundingBoxIn);
            }

            this.setBlockState(worldIn, Blocks.field_150406_ce.func_176203_a(i1), 10, 0, 7, structureBoundingBoxIn);
            this.setBlockState(worldIn, Blocks.field_150406_ce.func_176203_a(i1), 10, 0, 8, structureBoundingBoxIn);
            this.setBlockState(worldIn, Blocks.field_150406_ce.func_176203_a(i1), 9, 0, 9, structureBoundingBoxIn);
            this.setBlockState(worldIn, Blocks.field_150406_ce.func_176203_a(i1), 11, 0, 9, structureBoundingBoxIn);
            this.setBlockState(worldIn, Blocks.field_150406_ce.func_176203_a(i1), 8, 0, 10, structureBoundingBoxIn);
            this.setBlockState(worldIn, Blocks.field_150406_ce.func_176203_a(i1), 12, 0, 10, structureBoundingBoxIn);
            this.setBlockState(worldIn, Blocks.field_150406_ce.func_176203_a(i1), 7, 0, 10, structureBoundingBoxIn);
            this.setBlockState(worldIn, Blocks.field_150406_ce.func_176203_a(i1), 13, 0, 10, structureBoundingBoxIn);
            this.setBlockState(worldIn, Blocks.field_150406_ce.func_176203_a(i1), 9, 0, 11, structureBoundingBoxIn);
            this.setBlockState(worldIn, Blocks.field_150406_ce.func_176203_a(i1), 11, 0, 11, structureBoundingBoxIn);
            this.setBlockState(worldIn, Blocks.field_150406_ce.func_176203_a(i1), 10, 0, 12, structureBoundingBoxIn);
            this.setBlockState(worldIn, Blocks.field_150406_ce.func_176203_a(i1), 10, 0, 13, structureBoundingBoxIn);
            this.setBlockState(worldIn, Blocks.field_150406_ce.func_176203_a(j1), 10, 0, 10, structureBoundingBoxIn);

            for (int j3 = 0; j3 <= this.scatteredFeatureSizeX - 1; j3 += this.scatteredFeatureSizeX - 1)
            {
                this.setBlockState(worldIn, Blocks.sandstone.func_176203_a(BlockSandStone.EnumType.SMOOTH.getMetadata()), j3, 2, 1, structureBoundingBoxIn);
                this.setBlockState(worldIn, Blocks.field_150406_ce.func_176203_a(i1), j3, 2, 2, structureBoundingBoxIn);
                this.setBlockState(worldIn, Blocks.sandstone.func_176203_a(BlockSandStone.EnumType.SMOOTH.getMetadata()), j3, 2, 3, structureBoundingBoxIn);
                this.setBlockState(worldIn, Blocks.sandstone.func_176203_a(BlockSandStone.EnumType.SMOOTH.getMetadata()), j3, 3, 1, structureBoundingBoxIn);
                this.setBlockState(worldIn, Blocks.field_150406_ce.func_176203_a(i1), j3, 3, 2, structureBoundingBoxIn);
                this.setBlockState(worldIn, Blocks.sandstone.func_176203_a(BlockSandStone.EnumType.SMOOTH.getMetadata()), j3, 3, 3, structureBoundingBoxIn);
                this.setBlockState(worldIn, Blocks.field_150406_ce.func_176203_a(i1), j3, 4, 1, structureBoundingBoxIn);
                this.setBlockState(worldIn, Blocks.sandstone.func_176203_a(BlockSandStone.EnumType.CHISELED.getMetadata()), j3, 4, 2, structureBoundingBoxIn);
                this.setBlockState(worldIn, Blocks.field_150406_ce.func_176203_a(i1), j3, 4, 3, structureBoundingBoxIn);
                this.setBlockState(worldIn, Blocks.sandstone.func_176203_a(BlockSandStone.EnumType.SMOOTH.getMetadata()), j3, 5, 1, structureBoundingBoxIn);
                this.setBlockState(worldIn, Blocks.field_150406_ce.func_176203_a(i1), j3, 5, 2, structureBoundingBoxIn);
                this.setBlockState(worldIn, Blocks.sandstone.func_176203_a(BlockSandStone.EnumType.SMOOTH.getMetadata()), j3, 5, 3, structureBoundingBoxIn);
                this.setBlockState(worldIn, Blocks.field_150406_ce.func_176203_a(i1), j3, 6, 1, structureBoundingBoxIn);
                this.setBlockState(worldIn, Blocks.sandstone.func_176203_a(BlockSandStone.EnumType.CHISELED.getMetadata()), j3, 6, 2, structureBoundingBoxIn);
                this.setBlockState(worldIn, Blocks.field_150406_ce.func_176203_a(i1), j3, 6, 3, structureBoundingBoxIn);
                this.setBlockState(worldIn, Blocks.field_150406_ce.func_176203_a(i1), j3, 7, 1, structureBoundingBoxIn);
                this.setBlockState(worldIn, Blocks.field_150406_ce.func_176203_a(i1), j3, 7, 2, structureBoundingBoxIn);
                this.setBlockState(worldIn, Blocks.field_150406_ce.func_176203_a(i1), j3, 7, 3, structureBoundingBoxIn);
                this.setBlockState(worldIn, Blocks.sandstone.func_176203_a(BlockSandStone.EnumType.SMOOTH.getMetadata()), j3, 8, 1, structureBoundingBoxIn);
                this.setBlockState(worldIn, Blocks.sandstone.func_176203_a(BlockSandStone.EnumType.SMOOTH.getMetadata()), j3, 8, 2, structureBoundingBoxIn);
                this.setBlockState(worldIn, Blocks.sandstone.func_176203_a(BlockSandStone.EnumType.SMOOTH.getMetadata()), j3, 8, 3, structureBoundingBoxIn);
            }

            for (int k3 = 2; k3 <= this.scatteredFeatureSizeX - 3; k3 += this.scatteredFeatureSizeX - 3 - 2)
            {
                this.setBlockState(worldIn, Blocks.sandstone.func_176203_a(BlockSandStone.EnumType.SMOOTH.getMetadata()), k3 - 1, 2, 0, structureBoundingBoxIn);
                this.setBlockState(worldIn, Blocks.field_150406_ce.func_176203_a(i1), k3, 2, 0, structureBoundingBoxIn);
                this.setBlockState(worldIn, Blocks.sandstone.func_176203_a(BlockSandStone.EnumType.SMOOTH.getMetadata()), k3 + 1, 2, 0, structureBoundingBoxIn);
                this.setBlockState(worldIn, Blocks.sandstone.func_176203_a(BlockSandStone.EnumType.SMOOTH.getMetadata()), k3 - 1, 3, 0, structureBoundingBoxIn);
                this.setBlockState(worldIn, Blocks.field_150406_ce.func_176203_a(i1), k3, 3, 0, structureBoundingBoxIn);
                this.setBlockState(worldIn, Blocks.sandstone.func_176203_a(BlockSandStone.EnumType.SMOOTH.getMetadata()), k3 + 1, 3, 0, structureBoundingBoxIn);
                this.setBlockState(worldIn, Blocks.field_150406_ce.func_176203_a(i1), k3 - 1, 4, 0, structureBoundingBoxIn);
                this.setBlockState(worldIn, Blocks.sandstone.func_176203_a(BlockSandStone.EnumType.CHISELED.getMetadata()), k3, 4, 0, structureBoundingBoxIn);
                this.setBlockState(worldIn, Blocks.field_150406_ce.func_176203_a(i1), k3 + 1, 4, 0, structureBoundingBoxIn);
                this.setBlockState(worldIn, Blocks.sandstone.func_176203_a(BlockSandStone.EnumType.SMOOTH.getMetadata()), k3 - 1, 5, 0, structureBoundingBoxIn);
                this.setBlockState(worldIn, Blocks.field_150406_ce.func_176203_a(i1), k3, 5, 0, structureBoundingBoxIn);
                this.setBlockState(worldIn, Blocks.sandstone.func_176203_a(BlockSandStone.EnumType.SMOOTH.getMetadata()), k3 + 1, 5, 0, structureBoundingBoxIn);
                this.setBlockState(worldIn, Blocks.field_150406_ce.func_176203_a(i1), k3 - 1, 6, 0, structureBoundingBoxIn);
                this.setBlockState(worldIn, Blocks.sandstone.func_176203_a(BlockSandStone.EnumType.CHISELED.getMetadata()), k3, 6, 0, structureBoundingBoxIn);
                this.setBlockState(worldIn, Blocks.field_150406_ce.func_176203_a(i1), k3 + 1, 6, 0, structureBoundingBoxIn);
                this.setBlockState(worldIn, Blocks.field_150406_ce.func_176203_a(i1), k3 - 1, 7, 0, structureBoundingBoxIn);
                this.setBlockState(worldIn, Blocks.field_150406_ce.func_176203_a(i1), k3, 7, 0, structureBoundingBoxIn);
                this.setBlockState(worldIn, Blocks.field_150406_ce.func_176203_a(i1), k3 + 1, 7, 0, structureBoundingBoxIn);
                this.setBlockState(worldIn, Blocks.sandstone.func_176203_a(BlockSandStone.EnumType.SMOOTH.getMetadata()), k3 - 1, 8, 0, structureBoundingBoxIn);
                this.setBlockState(worldIn, Blocks.sandstone.func_176203_a(BlockSandStone.EnumType.SMOOTH.getMetadata()), k3, 8, 0, structureBoundingBoxIn);
                this.setBlockState(worldIn, Blocks.sandstone.func_176203_a(BlockSandStone.EnumType.SMOOTH.getMetadata()), k3 + 1, 8, 0, structureBoundingBoxIn);
            }

            this.fillWithBlocks(worldIn, structureBoundingBoxIn, 8, 4, 0, 12, 6, 0, Blocks.sandstone.func_176203_a(BlockSandStone.EnumType.SMOOTH.getMetadata()), Blocks.sandstone.func_176203_a(BlockSandStone.EnumType.SMOOTH.getMetadata()), false);
            this.setBlockState(worldIn, Blocks.field_150350_a.func_176223_P(), 8, 6, 0, structureBoundingBoxIn);
            this.setBlockState(worldIn, Blocks.field_150350_a.func_176223_P(), 12, 6, 0, structureBoundingBoxIn);
            this.setBlockState(worldIn, Blocks.field_150406_ce.func_176203_a(i1), 9, 5, 0, structureBoundingBoxIn);
            this.setBlockState(worldIn, Blocks.sandstone.func_176203_a(BlockSandStone.EnumType.CHISELED.getMetadata()), 10, 5, 0, structureBoundingBoxIn);
            this.setBlockState(worldIn, Blocks.field_150406_ce.func_176203_a(i1), 11, 5, 0, structureBoundingBoxIn);
            this.fillWithBlocks(worldIn, structureBoundingBoxIn, 8, -14, 8, 12, -11, 12, Blocks.sandstone.func_176203_a(BlockSandStone.EnumType.SMOOTH.getMetadata()), Blocks.sandstone.func_176203_a(BlockSandStone.EnumType.SMOOTH.getMetadata()), false);
            this.fillWithBlocks(worldIn, structureBoundingBoxIn, 8, -10, 8, 12, -10, 12, Blocks.sandstone.func_176203_a(BlockSandStone.EnumType.CHISELED.getMetadata()), Blocks.sandstone.func_176203_a(BlockSandStone.EnumType.CHISELED.getMetadata()), false);
            this.fillWithBlocks(worldIn, structureBoundingBoxIn, 8, -9, 8, 12, -9, 12, Blocks.sandstone.func_176203_a(BlockSandStone.EnumType.SMOOTH.getMetadata()), Blocks.sandstone.func_176203_a(BlockSandStone.EnumType.SMOOTH.getMetadata()), false);
            this.fillWithBlocks(worldIn, structureBoundingBoxIn, 8, -8, 8, 12, -1, 12, Blocks.sandstone.func_176223_P(), Blocks.sandstone.func_176223_P(), false);
            this.fillWithBlocks(worldIn, structureBoundingBoxIn, 9, -11, 9, 11, -1, 11, Blocks.field_150350_a.func_176223_P(), Blocks.field_150350_a.func_176223_P(), false);
            this.setBlockState(worldIn, Blocks.stone_pressure_plate.func_176223_P(), 10, -11, 10, structureBoundingBoxIn);
            this.fillWithBlocks(worldIn, structureBoundingBoxIn, 9, -13, 9, 11, -13, 11, Blocks.field_150335_W.func_176223_P(), Blocks.field_150350_a.func_176223_P(), false);
            this.setBlockState(worldIn, Blocks.field_150350_a.func_176223_P(), 8, -11, 10, structureBoundingBoxIn);
            this.setBlockState(worldIn, Blocks.field_150350_a.func_176223_P(), 8, -10, 10, structureBoundingBoxIn);
            this.setBlockState(worldIn, Blocks.sandstone.func_176203_a(BlockSandStone.EnumType.CHISELED.getMetadata()), 7, -10, 10, structureBoundingBoxIn);
            this.setBlockState(worldIn, Blocks.sandstone.func_176203_a(BlockSandStone.EnumType.SMOOTH.getMetadata()), 7, -11, 10, structureBoundingBoxIn);
            this.setBlockState(worldIn, Blocks.field_150350_a.func_176223_P(), 12, -11, 10, structureBoundingBoxIn);
            this.setBlockState(worldIn, Blocks.field_150350_a.func_176223_P(), 12, -10, 10, structureBoundingBoxIn);
            this.setBlockState(worldIn, Blocks.sandstone.func_176203_a(BlockSandStone.EnumType.CHISELED.getMetadata()), 13, -10, 10, structureBoundingBoxIn);
            this.setBlockState(worldIn, Blocks.sandstone.func_176203_a(BlockSandStone.EnumType.SMOOTH.getMetadata()), 13, -11, 10, structureBoundingBoxIn);
            this.setBlockState(worldIn, Blocks.field_150350_a.func_176223_P(), 10, -11, 8, structureBoundingBoxIn);
            this.setBlockState(worldIn, Blocks.field_150350_a.func_176223_P(), 10, -10, 8, structureBoundingBoxIn);
            this.setBlockState(worldIn, Blocks.sandstone.func_176203_a(BlockSandStone.EnumType.CHISELED.getMetadata()), 10, -10, 7, structureBoundingBoxIn);
            this.setBlockState(worldIn, Blocks.sandstone.func_176203_a(BlockSandStone.EnumType.SMOOTH.getMetadata()), 10, -11, 7, structureBoundingBoxIn);
            this.setBlockState(worldIn, Blocks.field_150350_a.func_176223_P(), 10, -11, 12, structureBoundingBoxIn);
            this.setBlockState(worldIn, Blocks.field_150350_a.func_176223_P(), 10, -10, 12, structureBoundingBoxIn);
            this.setBlockState(worldIn, Blocks.sandstone.func_176203_a(BlockSandStone.EnumType.CHISELED.getMetadata()), 10, -10, 13, structureBoundingBoxIn);
            this.setBlockState(worldIn, Blocks.sandstone.func_176203_a(BlockSandStone.EnumType.SMOOTH.getMetadata()), 10, -11, 13, structureBoundingBoxIn);

            for (Object enumfacing0 : EnumFacing.Plane.HORIZONTAL)
            {
                EnumFacing enumfacing = (EnumFacing) enumfacing0;

                if (!this.field_74940_h[enumfacing.getHorizontalIndex()])
                {
                    int l1 = enumfacing.getFrontOffsetX() * 2;
                    int i2 = enumfacing.getFrontOffsetZ() * 2;
                    this.field_74940_h[enumfacing.getHorizontalIndex()] = this.generateChestContents(worldIn, structureBoundingBoxIn, randomIn, 10 + l1, -11, 10 + i2, WeightedRandomChestContent.func_177629_a(itemsToGenerateInTemple, new WeightedRandomChestContent[] {Items.field_151134_bR.getRandom(randomIn)}), 2 + randomIn.nextInt(5));
                }
            }

            return true;
        }
    }

    abstract static class Feature extends StructureComponent
    {
        protected int scatteredFeatureSizeX;
        protected int scatteredFeatureSizeY;
        protected int scatteredFeatureSizeZ;
        protected int field_74936_d = -1;

        public Feature()
        {
        }

        protected Feature(Random p_i2065_1_, int p_i2065_2_, int p_i2065_3_, int p_i2065_4_, int p_i2065_5_, int p_i2065_6_, int p_i2065_7_)
        {
            super(0);
            this.scatteredFeatureSizeX = p_i2065_5_;
            this.scatteredFeatureSizeY = p_i2065_6_;
            this.scatteredFeatureSizeZ = p_i2065_7_;
            this.coordBaseMode = EnumFacing.Plane.HORIZONTAL.random(p_i2065_1_);

            switch (this.coordBaseMode)
            {
                case NORTH:
                case SOUTH:
                    this.boundingBox = new StructureBoundingBox(p_i2065_2_, p_i2065_3_, p_i2065_4_, p_i2065_2_ + p_i2065_5_ - 1, p_i2065_3_ + p_i2065_6_ - 1, p_i2065_4_ + p_i2065_7_ - 1);
                    break;

                default:
                    this.boundingBox = new StructureBoundingBox(p_i2065_2_, p_i2065_3_, p_i2065_4_, p_i2065_2_ + p_i2065_7_ - 1, p_i2065_3_ + p_i2065_6_ - 1, p_i2065_4_ + p_i2065_5_ - 1);
            }
        }

        protected void writeStructureToNBT(NBTTagCompound tagCompound)
        {
            tagCompound.func_74768_a("Width", this.scatteredFeatureSizeX);
            tagCompound.func_74768_a("Height", this.scatteredFeatureSizeY);
            tagCompound.func_74768_a("Depth", this.scatteredFeatureSizeZ);
            tagCompound.func_74768_a("HPos", this.field_74936_d);
        }

        protected void readStructureFromNBT(NBTTagCompound tagCompound)
        {
            this.scatteredFeatureSizeX = tagCompound.getInteger("Width");
            this.scatteredFeatureSizeY = tagCompound.getInteger("Height");
            this.scatteredFeatureSizeZ = tagCompound.getInteger("Depth");
            this.field_74936_d = tagCompound.getInteger("HPos");
        }

        protected boolean func_74935_a(World worldIn, StructureBoundingBox p_74935_2_, int p_74935_3_)
        {
            if (this.field_74936_d >= 0)
            {
                return true;
            }
            else
            {
                int i = 0;
                int j = 0;
                BlockPos.MutableBlockPos blockpos$mutableblockpos = new BlockPos.MutableBlockPos();

                for (int k = this.boundingBox.field_78896_c; k <= this.boundingBox.field_78892_f; ++k)
                {
                    for (int l = this.boundingBox.field_78897_a; l <= this.boundingBox.field_78893_d; ++l)
                    {
                        blockpos$mutableblockpos.func_181079_c(l, 64, k);

                        if (p_74935_2_.func_175898_b(blockpos$mutableblockpos))
                        {
                            i += Math.max(worldIn.getTopSolidOrLiquidBlock(blockpos$mutableblockpos).func_177956_o(), worldIn.provider.getAverageGroundLevel());
                            ++j;
                        }
                    }
                }

                if (j == 0)
                {
                    return false;
                }
                else
                {
                    this.field_74936_d = i / j;
                    this.boundingBox.offset(0, this.field_74936_d - this.boundingBox.field_78895_b + p_74935_3_, 0);
                    return true;
                }
            }
        }
    }

    public static class JunglePyramid extends ComponentScatteredFeaturePieces.Feature
    {
        private boolean field_74947_h;
        private boolean field_74948_i;
        private boolean field_74945_j;
        private boolean field_74946_k;
        private static final List<WeightedRandomChestContent> field_175816_i = Lists.newArrayList(new WeightedRandomChestContent[] {new WeightedRandomChestContent(Items.field_151045_i, 0, 1, 3, 3), new WeightedRandomChestContent(Items.iron_ingot, 0, 1, 5, 10), new WeightedRandomChestContent(Items.gold_ingot, 0, 2, 7, 15), new WeightedRandomChestContent(Items.emerald, 0, 1, 3, 2), new WeightedRandomChestContent(Items.field_151103_aS, 0, 4, 6, 20), new WeightedRandomChestContent(Items.field_151078_bh, 0, 3, 7, 16), new WeightedRandomChestContent(Items.saddle, 0, 1, 1, 3), new WeightedRandomChestContent(Items.iron_horse_armor, 0, 1, 1, 1), new WeightedRandomChestContent(Items.golden_horse_armor, 0, 1, 1, 1), new WeightedRandomChestContent(Items.diamond_horse_armor, 0, 1, 1, 1)});
        private static final List<WeightedRandomChestContent> field_175815_j = Lists.newArrayList(new WeightedRandomChestContent[] {new WeightedRandomChestContent(Items.arrow, 0, 2, 7, 30)});
        private static ComponentScatteredFeaturePieces.JunglePyramid.Stones junglePyramidsRandomScatteredStones = new ComponentScatteredFeaturePieces.JunglePyramid.Stones();

        public JunglePyramid()
        {
        }

        public JunglePyramid(Random p_i2064_1_, int p_i2064_2_, int p_i2064_3_)
        {
            super(p_i2064_1_, p_i2064_2_, 64, p_i2064_3_, 12, 10, 15);
        }

        protected void writeStructureToNBT(NBTTagCompound tagCompound)
        {
            super.writeStructureToNBT(tagCompound);
            tagCompound.setBoolean("placedMainChest", this.field_74947_h);
            tagCompound.setBoolean("placedHiddenChest", this.field_74948_i);
            tagCompound.setBoolean("placedTrap1", this.field_74945_j);
            tagCompound.setBoolean("placedTrap2", this.field_74946_k);
        }

        protected void readStructureFromNBT(NBTTagCompound tagCompound)
        {
            super.readStructureFromNBT(tagCompound);
            this.field_74947_h = tagCompound.getBoolean("placedMainChest");
            this.field_74948_i = tagCompound.getBoolean("placedHiddenChest");
            this.field_74945_j = tagCompound.getBoolean("placedTrap1");
            this.field_74946_k = tagCompound.getBoolean("placedTrap2");
        }

        public boolean addComponentParts(World worldIn, Random randomIn, StructureBoundingBox structureBoundingBoxIn)
        {
            if (!this.func_74935_a(worldIn, structureBoundingBoxIn, 0))
            {
                return false;
            }
            else
            {
                int i = this.getMetadataWithOffset(Blocks.stone_stairs, 3);
                int j = this.getMetadataWithOffset(Blocks.stone_stairs, 2);
                int k = this.getMetadataWithOffset(Blocks.stone_stairs, 0);
                int l = this.getMetadataWithOffset(Blocks.stone_stairs, 1);
                this.fillWithRandomizedBlocks(worldIn, structureBoundingBoxIn, 0, -4, 0, this.scatteredFeatureSizeX - 1, 0, this.scatteredFeatureSizeZ - 1, false, randomIn, junglePyramidsRandomScatteredStones);
                this.fillWithRandomizedBlocks(worldIn, structureBoundingBoxIn, 2, 1, 2, 9, 2, 2, false, randomIn, junglePyramidsRandomScatteredStones);
                this.fillWithRandomizedBlocks(worldIn, structureBoundingBoxIn, 2, 1, 12, 9, 2, 12, false, randomIn, junglePyramidsRandomScatteredStones);
                this.fillWithRandomizedBlocks(worldIn, structureBoundingBoxIn, 2, 1, 3, 2, 2, 11, false, randomIn, junglePyramidsRandomScatteredStones);
                this.fillWithRandomizedBlocks(worldIn, structureBoundingBoxIn, 9, 1, 3, 9, 2, 11, false, randomIn, junglePyramidsRandomScatteredStones);
                this.fillWithRandomizedBlocks(worldIn, structureBoundingBoxIn, 1, 3, 1, 10, 6, 1, false, randomIn, junglePyramidsRandomScatteredStones);
                this.fillWithRandomizedBlocks(worldIn, structureBoundingBoxIn, 1, 3, 13, 10, 6, 13, false, randomIn, junglePyramidsRandomScatteredStones);
                this.fillWithRandomizedBlocks(worldIn, structureBoundingBoxIn, 1, 3, 2, 1, 6, 12, false, randomIn, junglePyramidsRandomScatteredStones);
                this.fillWithRandomizedBlocks(worldIn, structureBoundingBoxIn, 10, 3, 2, 10, 6, 12, false, randomIn, junglePyramidsRandomScatteredStones);
                this.fillWithRandomizedBlocks(worldIn, structureBoundingBoxIn, 2, 3, 2, 9, 3, 12, false, randomIn, junglePyramidsRandomScatteredStones);
                this.fillWithRandomizedBlocks(worldIn, structureBoundingBoxIn, 2, 6, 2, 9, 6, 12, false, randomIn, junglePyramidsRandomScatteredStones);
                this.fillWithRandomizedBlocks(worldIn, structureBoundingBoxIn, 3, 7, 3, 8, 7, 11, false, randomIn, junglePyramidsRandomScatteredStones);
                this.fillWithRandomizedBlocks(worldIn, structureBoundingBoxIn, 4, 8, 4, 7, 8, 10, false, randomIn, junglePyramidsRandomScatteredStones);
                this.fillWithAir(worldIn, structureBoundingBoxIn, 3, 1, 3, 8, 2, 11);
                this.fillWithAir(worldIn, structureBoundingBoxIn, 4, 3, 6, 7, 3, 9);
                this.fillWithAir(worldIn, structureBoundingBoxIn, 2, 4, 2, 9, 5, 12);
                this.fillWithAir(worldIn, structureBoundingBoxIn, 4, 6, 5, 7, 6, 9);
                this.fillWithAir(worldIn, structureBoundingBoxIn, 5, 7, 6, 6, 7, 8);
                this.fillWithAir(worldIn, structureBoundingBoxIn, 5, 1, 2, 6, 2, 2);
                this.fillWithAir(worldIn, structureBoundingBoxIn, 5, 2, 12, 6, 2, 12);
                this.fillWithAir(worldIn, structureBoundingBoxIn, 5, 5, 1, 6, 5, 1);
                this.fillWithAir(worldIn, structureBoundingBoxIn, 5, 5, 13, 6, 5, 13);
                this.setBlockState(worldIn, Blocks.field_150350_a.func_176223_P(), 1, 5, 5, structureBoundingBoxIn);
                this.setBlockState(worldIn, Blocks.field_150350_a.func_176223_P(), 10, 5, 5, structureBoundingBoxIn);
                this.setBlockState(worldIn, Blocks.field_150350_a.func_176223_P(), 1, 5, 9, structureBoundingBoxIn);
                this.setBlockState(worldIn, Blocks.field_150350_a.func_176223_P(), 10, 5, 9, structureBoundingBoxIn);

                for (int i1 = 0; i1 <= 14; i1 += 14)
                {
                    this.fillWithRandomizedBlocks(worldIn, structureBoundingBoxIn, 2, 4, i1, 2, 5, i1, false, randomIn, junglePyramidsRandomScatteredStones);
                    this.fillWithRandomizedBlocks(worldIn, structureBoundingBoxIn, 4, 4, i1, 4, 5, i1, false, randomIn, junglePyramidsRandomScatteredStones);
                    this.fillWithRandomizedBlocks(worldIn, structureBoundingBoxIn, 7, 4, i1, 7, 5, i1, false, randomIn, junglePyramidsRandomScatteredStones);
                    this.fillWithRandomizedBlocks(worldIn, structureBoundingBoxIn, 9, 4, i1, 9, 5, i1, false, randomIn, junglePyramidsRandomScatteredStones);
                }

                this.fillWithRandomizedBlocks(worldIn, structureBoundingBoxIn, 5, 6, 0, 6, 6, 0, false, randomIn, junglePyramidsRandomScatteredStones);

                for (int k1 = 0; k1 <= 11; k1 += 11)
                {
                    for (int j1 = 2; j1 <= 12; j1 += 2)
                    {
                        this.fillWithRandomizedBlocks(worldIn, structureBoundingBoxIn, k1, 4, j1, k1, 5, j1, false, randomIn, junglePyramidsRandomScatteredStones);
                    }

                    this.fillWithRandomizedBlocks(worldIn, structureBoundingBoxIn, k1, 6, 5, k1, 6, 5, false, randomIn, junglePyramidsRandomScatteredStones);
                    this.fillWithRandomizedBlocks(worldIn, structureBoundingBoxIn, k1, 6, 9, k1, 6, 9, false, randomIn, junglePyramidsRandomScatteredStones);
                }

                this.fillWithRandomizedBlocks(worldIn, structureBoundingBoxIn, 2, 7, 2, 2, 9, 2, false, randomIn, junglePyramidsRandomScatteredStones);
                this.fillWithRandomizedBlocks(worldIn, structureBoundingBoxIn, 9, 7, 2, 9, 9, 2, false, randomIn, junglePyramidsRandomScatteredStones);
                this.fillWithRandomizedBlocks(worldIn, structureBoundingBoxIn, 2, 7, 12, 2, 9, 12, false, randomIn, junglePyramidsRandomScatteredStones);
                this.fillWithRandomizedBlocks(worldIn, structureBoundingBoxIn, 9, 7, 12, 9, 9, 12, false, randomIn, junglePyramidsRandomScatteredStones);
                this.fillWithRandomizedBlocks(worldIn, structureBoundingBoxIn, 4, 9, 4, 4, 9, 4, false, randomIn, junglePyramidsRandomScatteredStones);
                this.fillWithRandomizedBlocks(worldIn, structureBoundingBoxIn, 7, 9, 4, 7, 9, 4, false, randomIn, junglePyramidsRandomScatteredStones);
                this.fillWithRandomizedBlocks(worldIn, structureBoundingBoxIn, 4, 9, 10, 4, 9, 10, false, randomIn, junglePyramidsRandomScatteredStones);
                this.fillWithRandomizedBlocks(worldIn, structureBoundingBoxIn, 7, 9, 10, 7, 9, 10, false, randomIn, junglePyramidsRandomScatteredStones);
                this.fillWithRandomizedBlocks(worldIn, structureBoundingBoxIn, 5, 9, 7, 6, 9, 7, false, randomIn, junglePyramidsRandomScatteredStones);
                this.setBlockState(worldIn, Blocks.stone_stairs.func_176203_a(i), 5, 9, 6, structureBoundingBoxIn);
                this.setBlockState(worldIn, Blocks.stone_stairs.func_176203_a(i), 6, 9, 6, structureBoundingBoxIn);
                this.setBlockState(worldIn, Blocks.stone_stairs.func_176203_a(j), 5, 9, 8, structureBoundingBoxIn);
                this.setBlockState(worldIn, Blocks.stone_stairs.func_176203_a(j), 6, 9, 8, structureBoundingBoxIn);
                this.setBlockState(worldIn, Blocks.stone_stairs.func_176203_a(i), 4, 0, 0, structureBoundingBoxIn);
                this.setBlockState(worldIn, Blocks.stone_stairs.func_176203_a(i), 5, 0, 0, structureBoundingBoxIn);
                this.setBlockState(worldIn, Blocks.stone_stairs.func_176203_a(i), 6, 0, 0, structureBoundingBoxIn);
                this.setBlockState(worldIn, Blocks.stone_stairs.func_176203_a(i), 7, 0, 0, structureBoundingBoxIn);
                this.setBlockState(worldIn, Blocks.stone_stairs.func_176203_a(i), 4, 1, 8, structureBoundingBoxIn);
                this.setBlockState(worldIn, Blocks.stone_stairs.func_176203_a(i), 4, 2, 9, structureBoundingBoxIn);
                this.setBlockState(worldIn, Blocks.stone_stairs.func_176203_a(i), 4, 3, 10, structureBoundingBoxIn);
                this.setBlockState(worldIn, Blocks.stone_stairs.func_176203_a(i), 7, 1, 8, structureBoundingBoxIn);
                this.setBlockState(worldIn, Blocks.stone_stairs.func_176203_a(i), 7, 2, 9, structureBoundingBoxIn);
                this.setBlockState(worldIn, Blocks.stone_stairs.func_176203_a(i), 7, 3, 10, structureBoundingBoxIn);
                this.fillWithRandomizedBlocks(worldIn, structureBoundingBoxIn, 4, 1, 9, 4, 1, 9, false, randomIn, junglePyramidsRandomScatteredStones);
                this.fillWithRandomizedBlocks(worldIn, structureBoundingBoxIn, 7, 1, 9, 7, 1, 9, false, randomIn, junglePyramidsRandomScatteredStones);
                this.fillWithRandomizedBlocks(worldIn, structureBoundingBoxIn, 4, 1, 10, 7, 2, 10, false, randomIn, junglePyramidsRandomScatteredStones);
                this.fillWithRandomizedBlocks(worldIn, structureBoundingBoxIn, 5, 4, 5, 6, 4, 5, false, randomIn, junglePyramidsRandomScatteredStones);
                this.setBlockState(worldIn, Blocks.stone_stairs.func_176203_a(k), 4, 4, 5, structureBoundingBoxIn);
                this.setBlockState(worldIn, Blocks.stone_stairs.func_176203_a(l), 7, 4, 5, structureBoundingBoxIn);

                for (int l1 = 0; l1 < 4; ++l1)
                {
                    this.setBlockState(worldIn, Blocks.stone_stairs.func_176203_a(j), 5, 0 - l1, 6 + l1, structureBoundingBoxIn);
                    this.setBlockState(worldIn, Blocks.stone_stairs.func_176203_a(j), 6, 0 - l1, 6 + l1, structureBoundingBoxIn);
                    this.fillWithAir(worldIn, structureBoundingBoxIn, 5, 0 - l1, 7 + l1, 6, 0 - l1, 9 + l1);
                }

                this.fillWithAir(worldIn, structureBoundingBoxIn, 1, -3, 12, 10, -1, 13);
                this.fillWithAir(worldIn, structureBoundingBoxIn, 1, -3, 1, 3, -1, 13);
                this.fillWithAir(worldIn, structureBoundingBoxIn, 1, -3, 1, 9, -1, 5);

                for (int i2 = 1; i2 <= 13; i2 += 2)
                {
                    this.fillWithRandomizedBlocks(worldIn, structureBoundingBoxIn, 1, -3, i2, 1, -2, i2, false, randomIn, junglePyramidsRandomScatteredStones);
                }

                for (int j2 = 2; j2 <= 12; j2 += 2)
                {
                    this.fillWithRandomizedBlocks(worldIn, structureBoundingBoxIn, 1, -1, j2, 3, -1, j2, false, randomIn, junglePyramidsRandomScatteredStones);
                }

                this.fillWithRandomizedBlocks(worldIn, structureBoundingBoxIn, 2, -2, 1, 5, -2, 1, false, randomIn, junglePyramidsRandomScatteredStones);
                this.fillWithRandomizedBlocks(worldIn, structureBoundingBoxIn, 7, -2, 1, 9, -2, 1, false, randomIn, junglePyramidsRandomScatteredStones);
                this.fillWithRandomizedBlocks(worldIn, structureBoundingBoxIn, 6, -3, 1, 6, -3, 1, false, randomIn, junglePyramidsRandomScatteredStones);
                this.fillWithRandomizedBlocks(worldIn, structureBoundingBoxIn, 6, -1, 1, 6, -1, 1, false, randomIn, junglePyramidsRandomScatteredStones);
                this.setBlockState(worldIn, Blocks.tripwire_hook.func_176203_a(this.getMetadataWithOffset(Blocks.tripwire_hook, EnumFacing.EAST.getHorizontalIndex())).withProperty(BlockTripWireHook.ATTACHED, Boolean.valueOf(true)), 1, -3, 8, structureBoundingBoxIn);
                this.setBlockState(worldIn, Blocks.tripwire_hook.func_176203_a(this.getMetadataWithOffset(Blocks.tripwire_hook, EnumFacing.WEST.getHorizontalIndex())).withProperty(BlockTripWireHook.ATTACHED, Boolean.valueOf(true)), 4, -3, 8, structureBoundingBoxIn);
                this.setBlockState(worldIn, Blocks.tripwire.func_176223_P().withProperty(BlockTripWire.ATTACHED, Boolean.valueOf(true)), 2, -3, 8, structureBoundingBoxIn);
                this.setBlockState(worldIn, Blocks.tripwire.func_176223_P().withProperty(BlockTripWire.ATTACHED, Boolean.valueOf(true)), 3, -3, 8, structureBoundingBoxIn);
                this.setBlockState(worldIn, Blocks.redstone_wire.func_176223_P(), 5, -3, 7, structureBoundingBoxIn);
                this.setBlockState(worldIn, Blocks.redstone_wire.func_176223_P(), 5, -3, 6, structureBoundingBoxIn);
                this.setBlockState(worldIn, Blocks.redstone_wire.func_176223_P(), 5, -3, 5, structureBoundingBoxIn);
                this.setBlockState(worldIn, Blocks.redstone_wire.func_176223_P(), 5, -3, 4, structureBoundingBoxIn);
                this.setBlockState(worldIn, Blocks.redstone_wire.func_176223_P(), 5, -3, 3, structureBoundingBoxIn);
                this.setBlockState(worldIn, Blocks.redstone_wire.func_176223_P(), 5, -3, 2, structureBoundingBoxIn);
                this.setBlockState(worldIn, Blocks.redstone_wire.func_176223_P(), 5, -3, 1, structureBoundingBoxIn);
                this.setBlockState(worldIn, Blocks.redstone_wire.func_176223_P(), 4, -3, 1, structureBoundingBoxIn);
                this.setBlockState(worldIn, Blocks.mossy_cobblestone.func_176223_P(), 3, -3, 1, structureBoundingBoxIn);

                if (!this.field_74945_j)
                {
                    this.field_74945_j = this.generateDispenserContents(worldIn, structureBoundingBoxIn, randomIn, 3, -2, 1, EnumFacing.NORTH.getIndex(), field_175815_j, 2);
                }

                this.setBlockState(worldIn, Blocks.vine.func_176203_a(15), 3, -2, 2, structureBoundingBoxIn);
                this.setBlockState(worldIn, Blocks.tripwire_hook.func_176203_a(this.getMetadataWithOffset(Blocks.tripwire_hook, EnumFacing.NORTH.getHorizontalIndex())).withProperty(BlockTripWireHook.ATTACHED, Boolean.valueOf(true)), 7, -3, 1, structureBoundingBoxIn);
                this.setBlockState(worldIn, Blocks.tripwire_hook.func_176203_a(this.getMetadataWithOffset(Blocks.tripwire_hook, EnumFacing.SOUTH.getHorizontalIndex())).withProperty(BlockTripWireHook.ATTACHED, Boolean.valueOf(true)), 7, -3, 5, structureBoundingBoxIn);
                this.setBlockState(worldIn, Blocks.tripwire.func_176223_P().withProperty(BlockTripWire.ATTACHED, Boolean.valueOf(true)), 7, -3, 2, structureBoundingBoxIn);
                this.setBlockState(worldIn, Blocks.tripwire.func_176223_P().withProperty(BlockTripWire.ATTACHED, Boolean.valueOf(true)), 7, -3, 3, structureBoundingBoxIn);
                this.setBlockState(worldIn, Blocks.tripwire.func_176223_P().withProperty(BlockTripWire.ATTACHED, Boolean.valueOf(true)), 7, -3, 4, structureBoundingBoxIn);
                this.setBlockState(worldIn, Blocks.redstone_wire.func_176223_P(), 8, -3, 6, structureBoundingBoxIn);
                this.setBlockState(worldIn, Blocks.redstone_wire.func_176223_P(), 9, -3, 6, structureBoundingBoxIn);
                this.setBlockState(worldIn, Blocks.redstone_wire.func_176223_P(), 9, -3, 5, structureBoundingBoxIn);
                this.setBlockState(worldIn, Blocks.mossy_cobblestone.func_176223_P(), 9, -3, 4, structureBoundingBoxIn);
                this.setBlockState(worldIn, Blocks.redstone_wire.func_176223_P(), 9, -2, 4, structureBoundingBoxIn);

                if (!this.field_74946_k)
                {
                    this.field_74946_k = this.generateDispenserContents(worldIn, structureBoundingBoxIn, randomIn, 9, -2, 3, EnumFacing.WEST.getIndex(), field_175815_j, 2);
                }

                this.setBlockState(worldIn, Blocks.vine.func_176203_a(15), 8, -1, 3, structureBoundingBoxIn);
                this.setBlockState(worldIn, Blocks.vine.func_176203_a(15), 8, -2, 3, structureBoundingBoxIn);

                if (!this.field_74947_h)
                {
                    this.field_74947_h = this.generateChestContents(worldIn, structureBoundingBoxIn, randomIn, 8, -3, 3, WeightedRandomChestContent.func_177629_a(field_175816_i, new WeightedRandomChestContent[] {Items.field_151134_bR.getRandom(randomIn)}), 2 + randomIn.nextInt(5));
                }

                this.setBlockState(worldIn, Blocks.mossy_cobblestone.func_176223_P(), 9, -3, 2, structureBoundingBoxIn);
                this.setBlockState(worldIn, Blocks.mossy_cobblestone.func_176223_P(), 8, -3, 1, structureBoundingBoxIn);
                this.setBlockState(worldIn, Blocks.mossy_cobblestone.func_176223_P(), 4, -3, 5, structureBoundingBoxIn);
                this.setBlockState(worldIn, Blocks.mossy_cobblestone.func_176223_P(), 5, -2, 5, structureBoundingBoxIn);
                this.setBlockState(worldIn, Blocks.mossy_cobblestone.func_176223_P(), 5, -1, 5, structureBoundingBoxIn);
                this.setBlockState(worldIn, Blocks.mossy_cobblestone.func_176223_P(), 6, -3, 5, structureBoundingBoxIn);
                this.setBlockState(worldIn, Blocks.mossy_cobblestone.func_176223_P(), 7, -2, 5, structureBoundingBoxIn);
                this.setBlockState(worldIn, Blocks.mossy_cobblestone.func_176223_P(), 7, -1, 5, structureBoundingBoxIn);
                this.setBlockState(worldIn, Blocks.mossy_cobblestone.func_176223_P(), 8, -3, 5, structureBoundingBoxIn);
                this.fillWithRandomizedBlocks(worldIn, structureBoundingBoxIn, 9, -1, 1, 9, -1, 5, false, randomIn, junglePyramidsRandomScatteredStones);
                this.fillWithAir(worldIn, structureBoundingBoxIn, 8, -3, 8, 10, -1, 10);
                this.setBlockState(worldIn, Blocks.stonebrick.func_176203_a(BlockStoneBrick.CHISELED_META), 8, -2, 11, structureBoundingBoxIn);
                this.setBlockState(worldIn, Blocks.stonebrick.func_176203_a(BlockStoneBrick.CHISELED_META), 9, -2, 11, structureBoundingBoxIn);
                this.setBlockState(worldIn, Blocks.stonebrick.func_176203_a(BlockStoneBrick.CHISELED_META), 10, -2, 11, structureBoundingBoxIn);
                this.setBlockState(worldIn, Blocks.field_150442_at.func_176203_a(BlockLever.getMetadataForFacing(EnumFacing.getFront(this.getMetadataWithOffset(Blocks.field_150442_at, EnumFacing.NORTH.getIndex())))), 8, -2, 12, structureBoundingBoxIn);
                this.setBlockState(worldIn, Blocks.field_150442_at.func_176203_a(BlockLever.getMetadataForFacing(EnumFacing.getFront(this.getMetadataWithOffset(Blocks.field_150442_at, EnumFacing.NORTH.getIndex())))), 9, -2, 12, structureBoundingBoxIn);
                this.setBlockState(worldIn, Blocks.field_150442_at.func_176203_a(BlockLever.getMetadataForFacing(EnumFacing.getFront(this.getMetadataWithOffset(Blocks.field_150442_at, EnumFacing.NORTH.getIndex())))), 10, -2, 12, structureBoundingBoxIn);
                this.fillWithRandomizedBlocks(worldIn, structureBoundingBoxIn, 8, -3, 8, 8, -3, 10, false, randomIn, junglePyramidsRandomScatteredStones);
                this.fillWithRandomizedBlocks(worldIn, structureBoundingBoxIn, 10, -3, 8, 10, -3, 10, false, randomIn, junglePyramidsRandomScatteredStones);
                this.setBlockState(worldIn, Blocks.mossy_cobblestone.func_176223_P(), 10, -2, 9, structureBoundingBoxIn);
                this.setBlockState(worldIn, Blocks.redstone_wire.func_176223_P(), 8, -2, 9, structureBoundingBoxIn);
                this.setBlockState(worldIn, Blocks.redstone_wire.func_176223_P(), 8, -2, 10, structureBoundingBoxIn);
                this.setBlockState(worldIn, Blocks.redstone_wire.func_176223_P(), 10, -1, 9, structureBoundingBoxIn);
                this.setBlockState(worldIn, Blocks.sticky_piston.func_176203_a(EnumFacing.UP.getIndex()), 9, -2, 8, structureBoundingBoxIn);
                this.setBlockState(worldIn, Blocks.sticky_piston.func_176203_a(this.getMetadataWithOffset(Blocks.sticky_piston, EnumFacing.WEST.getIndex())), 10, -2, 8, structureBoundingBoxIn);
                this.setBlockState(worldIn, Blocks.sticky_piston.func_176203_a(this.getMetadataWithOffset(Blocks.sticky_piston, EnumFacing.WEST.getIndex())), 10, -1, 8, structureBoundingBoxIn);
                this.setBlockState(worldIn, Blocks.field_150413_aR.func_176203_a(this.getMetadataWithOffset(Blocks.field_150413_aR, EnumFacing.NORTH.getHorizontalIndex())), 10, -2, 10, structureBoundingBoxIn);

                if (!this.field_74948_i)
                {
                    this.field_74948_i = this.generateChestContents(worldIn, structureBoundingBoxIn, randomIn, 9, -3, 10, WeightedRandomChestContent.func_177629_a(field_175816_i, new WeightedRandomChestContent[] {Items.field_151134_bR.getRandom(randomIn)}), 2 + randomIn.nextInt(5));
                }

                return true;
            }
        }

        static class Stones extends StructureComponent.BlockSelector
        {
            private Stones()
            {
            }

            public void selectBlocks(Random rand, int x, int y, int z, boolean p_75062_5_)
            {
                if (rand.nextFloat() < 0.4F)
                {
                    this.blockstate = Blocks.field_150347_e.func_176223_P();
                }
                else
                {
                    this.blockstate = Blocks.mossy_cobblestone.func_176223_P();
                }
            }
        }
    }

    public static class SwampHut extends ComponentScatteredFeaturePieces.Feature
    {
        private boolean hasWitch;

        public SwampHut()
        {
        }

        public SwampHut(Random p_i2066_1_, int p_i2066_2_, int p_i2066_3_)
        {
            super(p_i2066_1_, p_i2066_2_, 64, p_i2066_3_, 7, 7, 9);
        }

        protected void writeStructureToNBT(NBTTagCompound tagCompound)
        {
            super.writeStructureToNBT(tagCompound);
            tagCompound.setBoolean("Witch", this.hasWitch);
        }

        protected void readStructureFromNBT(NBTTagCompound tagCompound)
        {
            super.readStructureFromNBT(tagCompound);
            this.hasWitch = tagCompound.getBoolean("Witch");
        }

        public boolean addComponentParts(World worldIn, Random randomIn, StructureBoundingBox structureBoundingBoxIn)
        {
            if (!this.func_74935_a(worldIn, structureBoundingBoxIn, 0))
            {
                return false;
            }
            else
            {
                this.fillWithBlocks(worldIn, structureBoundingBoxIn, 1, 1, 1, 5, 1, 7, Blocks.field_150344_f.func_176203_a(BlockPlanks.EnumType.SPRUCE.getMetadata()), Blocks.field_150344_f.func_176203_a(BlockPlanks.EnumType.SPRUCE.getMetadata()), false);
                this.fillWithBlocks(worldIn, structureBoundingBoxIn, 1, 4, 2, 5, 4, 7, Blocks.field_150344_f.func_176203_a(BlockPlanks.EnumType.SPRUCE.getMetadata()), Blocks.field_150344_f.func_176203_a(BlockPlanks.EnumType.SPRUCE.getMetadata()), false);
                this.fillWithBlocks(worldIn, structureBoundingBoxIn, 2, 1, 0, 4, 1, 0, Blocks.field_150344_f.func_176203_a(BlockPlanks.EnumType.SPRUCE.getMetadata()), Blocks.field_150344_f.func_176203_a(BlockPlanks.EnumType.SPRUCE.getMetadata()), false);
                this.fillWithBlocks(worldIn, structureBoundingBoxIn, 2, 2, 2, 3, 3, 2, Blocks.field_150344_f.func_176203_a(BlockPlanks.EnumType.SPRUCE.getMetadata()), Blocks.field_150344_f.func_176203_a(BlockPlanks.EnumType.SPRUCE.getMetadata()), false);
                this.fillWithBlocks(worldIn, structureBoundingBoxIn, 1, 2, 3, 1, 3, 6, Blocks.field_150344_f.func_176203_a(BlockPlanks.EnumType.SPRUCE.getMetadata()), Blocks.field_150344_f.func_176203_a(BlockPlanks.EnumType.SPRUCE.getMetadata()), false);
                this.fillWithBlocks(worldIn, structureBoundingBoxIn, 5, 2, 3, 5, 3, 6, Blocks.field_150344_f.func_176203_a(BlockPlanks.EnumType.SPRUCE.getMetadata()), Blocks.field_150344_f.func_176203_a(BlockPlanks.EnumType.SPRUCE.getMetadata()), false);
                this.fillWithBlocks(worldIn, structureBoundingBoxIn, 2, 2, 7, 4, 3, 7, Blocks.field_150344_f.func_176203_a(BlockPlanks.EnumType.SPRUCE.getMetadata()), Blocks.field_150344_f.func_176203_a(BlockPlanks.EnumType.SPRUCE.getMetadata()), false);
                this.fillWithBlocks(worldIn, structureBoundingBoxIn, 1, 0, 2, 1, 3, 2, Blocks.log.func_176223_P(), Blocks.log.func_176223_P(), false);
                this.fillWithBlocks(worldIn, structureBoundingBoxIn, 5, 0, 2, 5, 3, 2, Blocks.log.func_176223_P(), Blocks.log.func_176223_P(), false);
                this.fillWithBlocks(worldIn, structureBoundingBoxIn, 1, 0, 7, 1, 3, 7, Blocks.log.func_176223_P(), Blocks.log.func_176223_P(), false);
                this.fillWithBlocks(worldIn, structureBoundingBoxIn, 5, 0, 7, 5, 3, 7, Blocks.log.func_176223_P(), Blocks.log.func_176223_P(), false);
                this.setBlockState(worldIn, Blocks.oak_fence.func_176223_P(), 2, 3, 2, structureBoundingBoxIn);
                this.setBlockState(worldIn, Blocks.oak_fence.func_176223_P(), 3, 3, 7, structureBoundingBoxIn);
                this.setBlockState(worldIn, Blocks.field_150350_a.func_176223_P(), 1, 3, 4, structureBoundingBoxIn);
                this.setBlockState(worldIn, Blocks.field_150350_a.func_176223_P(), 5, 3, 4, structureBoundingBoxIn);
                this.setBlockState(worldIn, Blocks.field_150350_a.func_176223_P(), 5, 3, 5, structureBoundingBoxIn);
                this.setBlockState(worldIn, Blocks.flower_pot.func_176223_P().withProperty(BlockFlowerPot.CONTENTS, BlockFlowerPot.EnumFlowerType.MUSHROOM_RED), 1, 3, 5, structureBoundingBoxIn);
                this.setBlockState(worldIn, Blocks.field_150462_ai.func_176223_P(), 3, 2, 6, structureBoundingBoxIn);
                this.setBlockState(worldIn, Blocks.cauldron.func_176223_P(), 4, 2, 6, structureBoundingBoxIn);
                this.setBlockState(worldIn, Blocks.oak_fence.func_176223_P(), 1, 2, 1, structureBoundingBoxIn);
                this.setBlockState(worldIn, Blocks.oak_fence.func_176223_P(), 5, 2, 1, structureBoundingBoxIn);
                int i = this.getMetadataWithOffset(Blocks.oak_stairs, 3);
                int j = this.getMetadataWithOffset(Blocks.oak_stairs, 1);
                int k = this.getMetadataWithOffset(Blocks.oak_stairs, 0);
                int l = this.getMetadataWithOffset(Blocks.oak_stairs, 2);
                this.fillWithBlocks(worldIn, structureBoundingBoxIn, 0, 4, 1, 6, 4, 1, Blocks.spruce_stairs.func_176203_a(i), Blocks.spruce_stairs.func_176203_a(i), false);
                this.fillWithBlocks(worldIn, structureBoundingBoxIn, 0, 4, 2, 0, 4, 7, Blocks.spruce_stairs.func_176203_a(k), Blocks.spruce_stairs.func_176203_a(k), false);
                this.fillWithBlocks(worldIn, structureBoundingBoxIn, 6, 4, 2, 6, 4, 7, Blocks.spruce_stairs.func_176203_a(j), Blocks.spruce_stairs.func_176203_a(j), false);
                this.fillWithBlocks(worldIn, structureBoundingBoxIn, 0, 4, 8, 6, 4, 8, Blocks.spruce_stairs.func_176203_a(l), Blocks.spruce_stairs.func_176203_a(l), false);

                for (int i1 = 2; i1 <= 7; i1 += 5)
                {
                    for (int j1 = 1; j1 <= 5; j1 += 4)
                    {
                        this.replaceAirAndLiquidDownwards(worldIn, Blocks.log.func_176223_P(), j1, -1, i1, structureBoundingBoxIn);
                    }
                }

                if (!this.hasWitch)
                {
                    int l1 = this.getXWithOffset(2, 5);
                    int i2 = this.getYWithOffset(2);
                    int k1 = this.getZWithOffset(2, 5);

                    if (structureBoundingBoxIn.func_175898_b(new BlockPos(l1, i2, k1)))
                    {
                        this.hasWitch = true;
                        EntityWitch entitywitch = new EntityWitch(worldIn);
                        entitywitch.func_70012_b((double)l1 + 0.5D, (double)i2, (double)k1 + 0.5D, 0.0F, 0.0F);
                        entitywitch.func_180482_a(worldIn.func_175649_E(new BlockPos(l1, i2, k1)), (IEntityLivingData)null);
                        worldIn.func_72838_d(entitywitch);
                    }
                }

                return true;
            }
        }
    }
}
